[2024-04-08T07:57:49.198+0000] {taskinstance.py:1979} INFO - Dependencies all met for dep_context=non-requeueable deps ti=<TaskInstance: dog_api_pipeline.get_dog_api manual__2024-04-08T07:55:22.662689+00:00 [queued]>
[2024-04-08T07:57:49.206+0000] {taskinstance.py:1979} INFO - Dependencies all met for dep_context=requeueable deps ti=<TaskInstance: dog_api_pipeline.get_dog_api manual__2024-04-08T07:55:22.662689+00:00 [queued]>
[2024-04-08T07:57:49.207+0000] {taskinstance.py:2193} INFO - Starting attempt 3 of 3
[2024-04-08T07:57:49.228+0000] {taskinstance.py:2217} INFO - Executing <Task(PythonOperator): get_dog_api> on 2024-04-08 07:55:22.662689+00:00
[2024-04-08T07:57:49.235+0000] {standard_task_runner.py:60} INFO - Started process 40421 to run task
[2024-04-08T07:57:49.238+0000] {standard_task_runner.py:87} INFO - Running: ['***', 'tasks', 'run', 'dog_api_pipeline', 'get_dog_api', 'manual__2024-04-08T07:55:22.662689+00:00', '--job-id', '8', '--raw', '--subdir', 'DAGS_FOLDER/dog_api_pipeline.py', '--cfg-path', '/tmp/tmpy_7x0zeg']
[2024-04-08T07:57:49.239+0000] {standard_task_runner.py:88} INFO - Job 8: Subtask get_dog_api
[2024-04-08T07:57:49.283+0000] {task_command.py:423} INFO - Running <TaskInstance: dog_api_pipeline.get_dog_api manual__2024-04-08T07:55:22.662689+00:00 [running]> on host 8056db226622
[2024-04-08T07:57:49.350+0000] {taskinstance.py:2513} INFO - Exporting env vars: AIRFLOW_CTX_DAG_OWNER='***' AIRFLOW_CTX_DAG_ID='dog_api_pipeline' AIRFLOW_CTX_TASK_ID='get_dog_api' AIRFLOW_CTX_EXECUTION_DATE='2024-04-08T07:55:22.662689+00:00' AIRFLOW_CTX_TRY_NUMBER='3' AIRFLOW_CTX_DAG_RUN_ID='manual__2024-04-08T07:55:22.662689+00:00'
[2024-04-08T07:57:49.743+0000] {taskinstance.py:2731} ERROR - Task failed with exception
Traceback (most recent call last):
  File "/home/airflow/.local/lib/python3.8/site-packages/airflow/models/taskinstance.py", line 444, in _execute_task
    result = _execute_callable(context=context, **execute_callable_kwargs)
  File "/home/airflow/.local/lib/python3.8/site-packages/airflow/models/taskinstance.py", line 414, in _execute_callable
    return execute_callable(context=context, **execute_callable_kwargs)
  File "/home/airflow/.local/lib/python3.8/site-packages/airflow/operators/python.py", line 200, in execute
    return_value = self.execute_callable()
  File "/home/airflow/.local/lib/python3.8/site-packages/airflow/operators/python.py", line 217, in execute_callable
    return self.python_callable(*self.op_args, **self.op_kwargs)
  File "/opt/airflow/dags/dog_api_pipeline.py", line 15, in _get_dog_api
    logging.info()
TypeError: info() missing 1 required positional argument: 'msg'
[2024-04-08T07:57:49.752+0000] {taskinstance.py:1149} INFO - Marking task as FAILED. dag_id=dog_api_pipeline, task_id=get_dog_api, execution_date=20240408T075522, start_date=20240408T075749, end_date=20240408T075749
[2024-04-08T07:57:49.774+0000] {standard_task_runner.py:107} ERROR - Failed to execute job 8 for task get_dog_api (info() missing 1 required positional argument: 'msg'; 40421)
[2024-04-08T07:57:49.814+0000] {local_task_job_runner.py:234} INFO - Task exited with return code 1
[2024-04-08T07:57:49.837+0000] {taskinstance.py:3312} INFO - 0 downstream tasks scheduled from follow-on schedule check
