[2024-04-08T11:58:25.471+0000] {taskinstance.py:1979} INFO - Dependencies all met for dep_context=non-requeueable deps ti=<TaskInstance: etl.process manual__2024-04-08T10:53:12.317255+00:00 [queued]>
[2024-04-08T11:58:25.478+0000] {taskinstance.py:1979} INFO - Dependencies all met for dep_context=requeueable deps ti=<TaskInstance: etl.process manual__2024-04-08T10:53:12.317255+00:00 [queued]>
[2024-04-08T11:58:25.479+0000] {taskinstance.py:2193} INFO - Starting attempt 16 of 16
[2024-04-08T11:58:25.498+0000] {taskinstance.py:2217} INFO - Executing <Task(PythonOperator): process> on 2024-04-08 10:53:12.317255+00:00
[2024-04-08T11:58:25.506+0000] {standard_task_runner.py:60} INFO - Started process 166420 to run task
[2024-04-08T11:58:25.509+0000] {standard_task_runner.py:87} INFO - Running: ['***', 'tasks', 'run', 'etl', 'process', 'manual__2024-04-08T10:53:12.317255+00:00', '--job-id', '43', '--raw', '--subdir', 'DAGS_FOLDER/etl.py', '--cfg-path', '/tmp/tmpx60bqi8p']
[2024-04-08T11:58:25.511+0000] {standard_task_runner.py:88} INFO - Job 43: Subtask process
[2024-04-08T11:58:25.555+0000] {task_command.py:423} INFO - Running <TaskInstance: etl.process manual__2024-04-08T10:53:12.317255+00:00 [running]> on host 8056db226622
[2024-04-08T11:58:25.654+0000] {taskinstance.py:2513} INFO - Exporting env vars: AIRFLOW_CTX_DAG_OWNER='***' AIRFLOW_CTX_DAG_ID='etl' AIRFLOW_CTX_TASK_ID='process' AIRFLOW_CTX_EXECUTION_DATE='2024-04-08T10:53:12.317255+00:00' AIRFLOW_CTX_TRY_NUMBER='16' AIRFLOW_CTX_DAG_RUN_ID='manual__2024-04-08T10:53:12.317255+00:00'
[2024-04-08T11:58:25.662+0000] {base.py:83} INFO - Using connection ID 'my_postgres_conn' for task execution.
[2024-04-08T11:58:25.677+0000] {logging_mixin.py:188} INFO - 23487963576 WatchEvent 44167236 evilgaoshu 6296790 spring-projects/spring-boot 2022-08-17T15:52:40Z
[2024-04-08T11:58:25.678+0000] {taskinstance.py:2731} ERROR - Task failed with exception
Traceback (most recent call last):
  File "/home/airflow/.local/lib/python3.8/site-packages/airflow/models/taskinstance.py", line 444, in _execute_task
    result = _execute_callable(context=context, **execute_callable_kwargs)
  File "/home/airflow/.local/lib/python3.8/site-packages/airflow/models/taskinstance.py", line 414, in _execute_callable
    return execute_callable(context=context, **execute_callable_kwargs)
  File "/home/airflow/.local/lib/python3.8/site-packages/airflow/operators/python.py", line 200, in execute
    return_value = self.execute_callable()
  File "/home/airflow/.local/lib/python3.8/site-packages/airflow/operators/python.py", line 217, in execute_callable
    return self.python_callable(*self.op_args, **self.op_kwargs)
  File "/opt/airflow/dags/etl.py", line 108, in _process
    cur.execute(insert_statement)
psycopg2.errors.UndefinedTable: relation "actors" does not exist
LINE 2:                     INSERT INTO actors (
                                        ^

[2024-04-08T11:58:25.686+0000] {taskinstance.py:1149} INFO - Marking task as FAILED. dag_id=etl, task_id=process, execution_date=20240408T105312, start_date=20240408T115825, end_date=20240408T115825
[2024-04-08T11:58:25.699+0000] {standard_task_runner.py:107} ERROR - Failed to execute job 43 for task process (relation "actors" does not exist
LINE 2:                     INSERT INTO actors (
                                        ^
; 166420)
[2024-04-08T11:58:25.721+0000] {local_task_job_runner.py:234} INFO - Task exited with return code 1
[2024-04-08T11:58:25.736+0000] {taskinstance.py:3312} INFO - 0 downstream tasks scheduled from follow-on schedule check
