[2024-04-08T12:04:04.619+0000] {taskinstance.py:1979} INFO - Dependencies all met for dep_context=non-requeueable deps ti=<TaskInstance: etl.process manual__2024-04-08T10:53:12.317255+00:00 [queued]>
[2024-04-08T12:04:04.628+0000] {taskinstance.py:1979} INFO - Dependencies all met for dep_context=requeueable deps ti=<TaskInstance: etl.process manual__2024-04-08T10:53:12.317255+00:00 [queued]>
[2024-04-08T12:04:04.628+0000] {taskinstance.py:2193} INFO - Starting attempt 18 of 18
[2024-04-08T12:04:04.647+0000] {taskinstance.py:2217} INFO - Executing <Task(PythonOperator): process> on 2024-04-08 10:53:12.317255+00:00
[2024-04-08T12:04:04.656+0000] {standard_task_runner.py:60} INFO - Started process 169434 to run task
[2024-04-08T12:04:04.663+0000] {standard_task_runner.py:87} INFO - Running: ['***', 'tasks', 'run', 'etl', 'process', 'manual__2024-04-08T10:53:12.317255+00:00', '--job-id', '45', '--raw', '--subdir', 'DAGS_FOLDER/etl.py', '--cfg-path', '/tmp/tmprbyg_08d']
[2024-04-08T12:04:04.666+0000] {standard_task_runner.py:88} INFO - Job 45: Subtask process
[2024-04-08T12:04:04.734+0000] {task_command.py:423} INFO - Running <TaskInstance: etl.process manual__2024-04-08T10:53:12.317255+00:00 [running]> on host 8056db226622
[2024-04-08T12:04:04.844+0000] {taskinstance.py:2513} INFO - Exporting env vars: AIRFLOW_CTX_DAG_OWNER='***' AIRFLOW_CTX_DAG_ID='etl' AIRFLOW_CTX_TASK_ID='process' AIRFLOW_CTX_EXECUTION_DATE='2024-04-08T10:53:12.317255+00:00' AIRFLOW_CTX_TRY_NUMBER='18' AIRFLOW_CTX_DAG_RUN_ID='manual__2024-04-08T10:53:12.317255+00:00'
[2024-04-08T12:04:04.851+0000] {base.py:83} INFO - Using connection ID 'my_postgres_conn' for task execution.
[2024-04-08T12:04:04.865+0000] {logging_mixin.py:188} INFO - 23487963576 WatchEvent 44167236 evilgaoshu 6296790 spring-projects/spring-boot 2022-08-17T15:52:40Z
[2024-04-08T12:04:04.866+0000] {taskinstance.py:2731} ERROR - Task failed with exception
Traceback (most recent call last):
  File "/home/airflow/.local/lib/python3.8/site-packages/airflow/models/taskinstance.py", line 444, in _execute_task
    result = _execute_callable(context=context, **execute_callable_kwargs)
  File "/home/airflow/.local/lib/python3.8/site-packages/airflow/models/taskinstance.py", line 414, in _execute_callable
    return execute_callable(context=context, **execute_callable_kwargs)
  File "/home/airflow/.local/lib/python3.8/site-packages/airflow/operators/python.py", line 200, in execute
    return_value = self.execute_callable()
  File "/home/airflow/.local/lib/python3.8/site-packages/airflow/operators/python.py", line 217, in execute_callable
    return self.python_callable(*self.op_args, **self.op_kwargs)
  File "/opt/airflow/dags/etl.py", line 108, in _process
    cur.execute(insert_statement)
psycopg2.errors.UndefinedTable: relation "actors" does not exist
LINE 2:                     INSERT INTO actors (
                                        ^

[2024-04-08T12:04:04.872+0000] {taskinstance.py:1149} INFO - Marking task as FAILED. dag_id=etl, task_id=process, execution_date=20240408T105312, start_date=20240408T120404, end_date=20240408T120404
[2024-04-08T12:04:04.887+0000] {standard_task_runner.py:107} ERROR - Failed to execute job 45 for task process (relation "actors" does not exist
LINE 2:                     INSERT INTO actors (
                                        ^
; 169434)
[2024-04-08T12:04:04.924+0000] {local_task_job_runner.py:234} INFO - Task exited with return code 1
[2024-04-08T12:04:04.938+0000] {taskinstance.py:3312} INFO - 0 downstream tasks scheduled from follow-on schedule check
