[2024-04-08T10:29:58.450+0000] {taskinstance.py:1979} INFO - Dependencies all met for dep_context=non-requeueable deps ti=<TaskInstance: etl.get_files manual__2024-04-08T10:29:54.815147+00:00 [queued]>
[2024-04-08T10:29:58.458+0000] {taskinstance.py:1979} INFO - Dependencies all met for dep_context=requeueable deps ti=<TaskInstance: etl.get_files manual__2024-04-08T10:29:54.815147+00:00 [queued]>
[2024-04-08T10:29:58.459+0000] {taskinstance.py:2193} INFO - Starting attempt 1 of 1
[2024-04-08T10:29:58.482+0000] {taskinstance.py:2217} INFO - Executing <Task(PythonOperator): get_files> on 2024-04-08 10:29:54.815147+00:00
[2024-04-08T10:29:58.494+0000] {standard_task_runner.py:60} INFO - Started process 119484 to run task
[2024-04-08T10:29:58.509+0000] {standard_task_runner.py:87} INFO - Running: ['***', 'tasks', 'run', 'etl', 'get_files', 'manual__2024-04-08T10:29:54.815147+00:00', '--job-id', '12', '--raw', '--subdir', 'DAGS_FOLDER/etl.py', '--cfg-path', '/tmp/tmp3bgfa9h0']
[2024-04-08T10:29:58.512+0000] {standard_task_runner.py:88} INFO - Job 12: Subtask get_files
[2024-04-08T10:29:58.575+0000] {task_command.py:423} INFO - Running <TaskInstance: etl.get_files manual__2024-04-08T10:29:54.815147+00:00 [running]> on host 8056db226622
[2024-04-08T10:29:58.692+0000] {taskinstance.py:2513} INFO - Exporting env vars: AIRFLOW_CTX_DAG_OWNER='***' AIRFLOW_CTX_DAG_ID='etl' AIRFLOW_CTX_TASK_ID='get_files' AIRFLOW_CTX_EXECUTION_DATE='2024-04-08T10:29:54.815147+00:00' AIRFLOW_CTX_TRY_NUMBER='1' AIRFLOW_CTX_DAG_RUN_ID='manual__2024-04-08T10:29:54.815147+00:00'
[2024-04-08T10:29:58.697+0000] {taskinstance.py:2731} ERROR - Task failed with exception
Traceback (most recent call last):
  File "/home/airflow/.local/lib/python3.8/site-packages/airflow/models/taskinstance.py", line 444, in _execute_task
    result = _execute_callable(context=context, **execute_callable_kwargs)
  File "/home/airflow/.local/lib/python3.8/site-packages/airflow/models/taskinstance.py", line 414, in _execute_callable
    return execute_callable(context=context, **execute_callable_kwargs)
  File "/home/airflow/.local/lib/python3.8/site-packages/airflow/operators/python.py", line 200, in execute
    return_value = self.execute_callable()
  File "/home/airflow/.local/lib/python3.8/site-packages/airflow/operators/python.py", line 217, in execute_callable
    return self.python_callable(*self.op_args, **self.op_kwargs)
  File "/opt/airflow/dags/etl.py", line 13, in _get_files
    for root, dirs, files in os.walk(filepath):
NameError: name 'os' is not defined
[2024-04-08T10:29:58.706+0000] {taskinstance.py:1149} INFO - Marking task as FAILED. dag_id=etl, task_id=get_files, execution_date=20240408T102954, start_date=20240408T102958, end_date=20240408T102958
[2024-04-08T10:29:58.725+0000] {standard_task_runner.py:107} ERROR - Failed to execute job 12 for task get_files (name 'os' is not defined; 119484)
[2024-04-08T10:29:58.761+0000] {local_task_job_runner.py:234} INFO - Task exited with return code 1
[2024-04-08T10:29:58.799+0000] {taskinstance.py:3312} INFO - 0 downstream tasks scheduled from follow-on schedule check
